<?xml version="1.0" ?>
<sdf version='1.5'>
	<model name='wrv3'>
		<pose>0.0 0.0 0.0 0.0 0.0 0.0</pose>

		<!--LINKS-->

		<link name='base_footprint'/>

		<link name="base_link">
      <inertial>
        <pose>0 0 0.0875 0 0 0</pose>
        <inertia>
          <ixx>0.026</ixx>
          <ixy>0</ixy>
          <ixz>0</ixz>
          <iyy>0.055</iyy>
          <iyz>0</iyz>
          <izz>0.075</izz>
        </inertia>
        <mass>6.935</mass>
      </inertial>
      <collision name="base_link_collision">
        <pose>0 0 0.0875 0 0 0</pose>
        <geometry>
          <mesh>
            <uri>model://wrv3/meshes/base_link.stl</uri>
            <scale>0.01 0.01 0.01</scale>
          </mesh>
        </geometry>
      </collision>
      <visual name="base_link_visual">
        <pose>0 0 0.0875 0 0 0</pose>
        <geometry>
          <mesh>
            <uri>model://wrv3/meshes/base_link.stl</uri>
            <scale>0.01 0.01 0.01</scale>
          </mesh>
        </geometry>
      </visual>
    </link>

		<link name="wheell_link">
      <inertial>
        <pose>-0.05 0.1125 0.05 -1.57 0 0</pose>
        <inertia>
          <ixx>2.05e-04</ixx>
          <ixy>0</ixy>
          <ixz>0</ixz>
          <iyy>2.05e-04</iyy>
          <iyz>0</iyz>
          <izz>7.58e-04</izz>
        </inertia>
        <mass>0.303</mass>
      </inertial>
      <collision name="wheell_link_collision">
        <pose>-0.05 0.1125 0.05 -1.57 0 0</pose>
        <geometry>
          <mesh>
            <uri>model://wrv3/meshes/wheel.stl</uri>
            <scale>0.01 0.01 0.01</scale>
          </mesh>
        </geometry>
				<surface>
          <!-- This friction pamareter don't contain reliable data!! -->
          <friction>
            <ode>
              <mu>100000.0</mu>
              <mu2>100000.0</mu2>
              <fdir1>0 0 0</fdir1>
              <slip1>0.0</slip1>
              <slip2>0.0</slip2>
            </ode>
          </friction>
          <contact>
            <ode>
              <soft_cfm>0</soft_cfm>
              <soft_erp>0.2</soft_erp>
              <kp>1e+5</kp>
              <kd>1</kd>
              <max_vel>0.01</max_vel>
              <min_depth>0.001</min_depth>
            </ode>
          </contact>
        </surface>
      </collision>
      <visual name="wheell_link_visual">
        <pose>-0.05 0.1125 0.05 -1.57 0 0</pose>
        <geometry>
          <mesh>
            <uri>model://wrv3/meshes/wheel.stl</uri>
            <scale>0.01 0.01 0.01</scale>
          </mesh>
        </geometry>
      </visual>
    </link>

		<link name="wheelr_link">
      <inertial>
        <pose>-0.05 -0.1125 0.05 -1.57 0 0</pose>
        <inertia>
          <ixx>2.05e-04</ixx>
          <ixy>0</ixy>
          <ixz>0</ixz>
          <iyy>2.05e-04</iyy>
          <iyz>0</iyz>
          <izz>7.58e-04</izz>
        </inertia>
        <mass>0.303</mass>
      </inertial>
      <collision name="wheelr_link_collision">
        <pose>-0.05 -0.1125 0.05 -1.57 0 0</pose>
        <geometry>
          <mesh>
            <uri>model://wrv3/meshes/wheel.stl</uri>
            <scale>0.01 0.01 0.01</scale>
          </mesh>
        </geometry>
				<surface>
          <!-- This friction pamareter don't contain reliable data!! -->
          <friction>
            <ode>
              <mu>100000.0</mu>
              <mu2>100000.0</mu2>
              <fdir1>0 0 0</fdir1>
              <slip1>0.0</slip1>
              <slip2>0.0</slip2>
            </ode>
          </friction>
          <contact>
            <ode>
              <soft_cfm>0</soft_cfm>
              <soft_erp>0.2</soft_erp>
              <kp>1e+5</kp>
              <kd>1</kd>
              <max_vel>0.01</max_vel>
              <min_depth>0.001</min_depth>
            </ode>
          </contact>
        </surface>
      </collision>
      <visual name="wheelr_link_visual">
        <pose>-0.05 -0.1125 0.05 -1.57 0 0</pose>
        <geometry>
          <mesh>
            <uri>model://wrv3/meshes/wheel.stl</uri>
            <scale>0.01 0.01 0.01</scale>
          </mesh>
        </geometry>
      </visual>
    </link>

		<link name="casterh_link">
      <inertial>
        <pose>0.1 0 0.0325 0 0 0</pose>
        <inertia>
          <ixx>3.25e-06</ixx>
          <ixy>0</ixy>
          <ixz>0</ixz>
          <iyy>3.25e-06</iyy>
          <iyz>0</iyz>
          <izz>3.31e-06</izz>
        </inertia>
        <mass>0.027</mass>
      </inertial>
      <collision name="casterh_link_collision">
        <pose>0.1 0 0.0325 0 0 0</pose>
        <geometry>
          <mesh>
            <uri>model://wrv3/meshes/casterhold.stl</uri>
            <scale>0.01 0.01 0.01</scale>
          </mesh>
        </geometry>
      </collision>
      <visual name="casterh_link_visual">
        <pose>0.1 0 0.0325 0 0 0</pose>
        <geometry>
          <mesh>
            <uri>model://wrv3/meshes/casterhold.stl</uri>
            <scale>0.01 0.01 0.01</scale>
          </mesh>
        </geometry>
      </visual>
    </link>

		<link name="casterw_link">
      <inertial>
        <pose>0 0 -0.015 0 0 0</pose>
        <inertia>
          <ixx>1.98e-06</ixx>
          <ixy>0</ixy>
          <ixz>0</ixz>
          <iyy>1.98e-06</iyy>
          <iyz>0</iyz>
          <izz>1.98e-06</izz>
        </inertia>
        <mass>0.022</mass>
      </inertial>
      <collision name="casterw_link_collision">
        <pose>0 0 -0.015 0 0 0</pose>
        <geometry>
          <mesh>
            <uri>model://wrv3/meshes/casterwheel.stl</uri>
            <scale>0.01 0.01 0.01</scale>
          </mesh>
        </geometry>
				<surface>
          <contact>
            <ode>
              <soft_cfm>0</soft_cfm>
              <soft_erp>0.2</soft_erp>
              <kp>1e+5</kp>
              <kd>1</kd>
              <max_vel>0.01</max_vel>
              <min_depth>0.001</min_depth>
            </ode>
          </contact>
        </surface>
      </collision>
      <visual name="casterw_link_visual">
        <pose>0 0 -0.015 0 0 0</pose>
        <geometry>
          <mesh>
            <uri>model://wrv3/meshes/casterwheel.stl</uri>
            <scale>0.01 0.01 0.01</scale>
          </mesh>
        </geometry>
      </visual>
    </link>

		<link name="camera_link">
      <inertial>
        <pose>0.165 0 0.0875 0 0 0</pose>
        <inertia>
          <ixx>1.47e-05</ixx>
          <ixy>0</ixy>
          <ixz>0</ixz>
          <iyy>1.03e-04</iyy>
          <iyz>0</iyz>
          <izz>1.05e-04</izz>
        </inertia>
        <mass>0.116</mass>
      </inertial>
      <collision name="camera_link_collision">
        <pose>0.165 0 0.0875 0 0 0</pose>
        <geometry>
          <mesh>
            <uri>model://wrv3/meshes/camera.stl</uri>
            <scale>0.01 0.01 0.01</scale>
          </mesh>
        </geometry>
      </collision>
      <visual name="camera_link_visual">
        <pose>0.165 0 0.0875 0 0 0</pose>
        <geometry>
          <mesh>
            <uri>model://wrv3/meshes/camera.stl</uri>
            <scale>0.01 0.01 0.01</scale>
          </mesh>
        </geometry>
      </visual>
    </link>

		<link name="camera_color_link">
			<sensor name='color_camera' type='camera'>
        <always_on>true</always_on>
        <visualize>true</visualize>
        <update_rate>30</update_rate>
        <camera name='camera'>
          <horizontal_fov>1.02974</horizontal_fov>
          <image>
            <width>640</width>
            <height>480</height>
            <format>R8G8B8</format>
          </image>
          <clip>
            <near>0.02</near>
            <far>300</far>
          </clip>
          <noise>
            <type>gaussian</type>
            <mean>0</mean>
            <stddev>0.007</stddev>
          </noise>
        </camera>
        <plugin name='camera_driver' filename='libgazebo_ros_camera.so'>
        </plugin>
      </sensor>
		</link>

		<link name="lidar_link">
      <inertial>
        <pose>0.1 0 0.14 0 0 0</pose>
        <inertia>
          <ixx>1.1e-04</ixx>
          <ixy>0</ixy>
          <ixz>0</ixz>
          <iyy>1.1e-04</iyy>
          <iyz>0</iyz>
          <izz>3.09e-05</izz>
        </inertia>
        <mass>0.232</mass>
      </inertial>
      <collision name="lidar_link_collision">
        <pose>0.1 0 0.14 0 0 0</pose>
        <geometry>
          <mesh>
            <uri>model://wrv3/meshes/lidar.stl</uri>
            <scale>0.01 0.01 0.01</scale>
          </mesh>
        </geometry>
      </collision>
      <visual name="lidar_link_visual">
        <pose>0.1 0 0.14 0 0 0</pose>
        <geometry>
          <mesh>
            <uri>model://wrv3/meshes/lidar.stl</uri>
            <scale>0.01 0.01 0.01</scale>
          </mesh>
        </geometry>
      </visual>
			<sensor name='lidar' type='ray'>
        <always_on>1</always_on>
        <visualize>1</visualize>
        <update_rate>20</update_rate>
        <ray>
          <scan>
            <horizontal>
              <samples>360</samples>
              <resolution>1</resolution>
              <min_angle>0</min_angle>
              <max_angle>6.28</max_angle>
            </horizontal>
          </scan>
          <range>
            <min>0.12</min>
            <max>3.5</max>
            <resolution>0.015</resolution>
          </range>
          <noise>
            <type>gaussian</type>
            <mean>0</mean>
            <stddev>0.01</stddev>
          </noise>
        </ray>
        <plugin name='scan' filename='libgazebo_ros_ray_sensor.so'>
          <ros>
            <remapping>~/out:=scan</remapping>
          </ros>
          <output_type>sensor_msgs/LaserScan</output_type>
          <frame_name>lidar_link</frame_name>
        </plugin>
        <pose>0.1 0 0.14 0 -0 0</pose>
      </sensor>
    </link>

		<link name="imu_link">
      <inertial>
        <pose>0 0 0.135 0 0 0</pose>
        <inertia>
          <ixx>8e-07</ixx>
          <ixy>0</ixy>
          <ixz>0</ixz>
          <iyy>8e-07</iyy>
          <iyz>0</iyz>
          <izz>8e-07</izz>
        </inertia>
        <mass>0.012</mass>
      </inertial>
      <collision name="imu_link_collision">
        <pose>0 0 0.135 0 0 0</pose>
        <geometry>
          <box>
            <size>0.02 0.02 0.02</size>
          </box>
        </geometry>
      </collision>
      <visual name="imu_link_visual">
        <pose>0 0 0.135 0 0 0</pose>
        <geometry>
          <box>
            <size>0.02 0.02 0.02</size>
          </box>
        </geometry>
      </visual>
      <sensor name="imu_sensor" type="imu">
        <always_on>true</always_on>
        <update_rate>100</update_rate>
				<visualize>true</visualize>
        <imu>
          <angular_velocity>
            <x>
              <noise type="gaussian">
                <mean>0.0</mean>
                <stddev>2e-4</stddev>
								<bias_mean>0.0000075</bias_mean>
            		<bias_stddev>0.0000008</bias_stddev>
              </noise>
            </x>
            <y>
              <noise type="gaussian">
                <mean>0.0</mean>
                <stddev>2e-4</stddev>
								<bias_mean>0.0000075</bias_mean>
            		<bias_stddev>0.0000008</bias_stddev>
              </noise>
            </y>
            <z>
              <noise type="gaussian">
                <mean>0.0</mean>
                <stddev>2e-4</stddev>
								<bias_mean>0.0000075</bias_mean>
          			<bias_stddev>0.0000008</bias_stddev>
              </noise>
            </z>
          </angular_velocity>
          <linear_acceleration>
            <x>
              <noise type="gaussian">
                <mean>0.0</mean>
                <stddev>1.7e-2</stddev>
								<bias_mean>0.1</bias_mean>
            		<bias_stddev>0.001</bias_stddev>
              </noise>
            </x>
            <y>
              <noise type="gaussian">
                <mean>0.0</mean>
                <stddev>1.7e-2</stddev>
								<bias_mean>0.1</bias_mean>
            		<bias_stddev>0.001</bias_stddev>
              </noise>
            </y>
            <z>
              <noise type="gaussian">
                <mean>0.0</mean>
                <stddev>1.7e-2</stddev>
								<bias_mean>0.1</bias_mean>
            		<bias_stddev>0.001</bias_stddev>
              </noise>
            </z>
          </linear_acceleration>
        </imu>
        <plugin name="wrv3_imu" filename="libgazebo_ros_imu_sensor.so">
          <ros>
            <!-- <namespace>/wrv3</namespace> -->
            <remapping>~/out:=imu</remapping>
          </ros>
        </plugin>
      </sensor>
    </link>

		<!--JOINTS-->

		<joint name="base_joint" type="fixed">
      <parent>base_footprint</parent>
      <child>base_link</child>
      <pose>0.0 0.0 0.0 0 0 0</pose>
    </joint>

		<joint name="wheell_joint" type="revolute">
      <parent>base_link</parent>
      <child>wheell_link</child>
      <pose>-0.05 0.1125 0.05 -1.57 0 0</pose>
      <axis>
        <xyz>0 0 1</xyz>
      </axis>
    </joint>

		<joint name="wheelr_joint" type="revolute">
      <parent>base_link</parent>
      <child>wheelr_link</child>
      <pose>-0.05 -0.1125 0.05 -1.57 0 0</pose>
      <axis>
        <xyz>0 0 1</xyz>
      </axis>
    </joint>

		<joint name="casterh_joint" type="fixed">
      <parent>base_link</parent>
      <child>casterh_link</child>
      <pose>0.1 0 0.0325 0 0 0</pose>
      <axis>
        <xyz>0 0 1</xyz>
      </axis>
    </joint>
		
		<joint name="casterw_joint" type="ball">
      <parent>casterh_link</parent>
      <child>casterw_link</child>
      <pose>0 0 -0.015 0 0 0</pose>
      <axis>
        <xyz>0 0 1</xyz>
      </axis>
    </joint>

		<joint name="camera_joint" type="fixed">
      <parent>base_link</parent>
      <child>camera_link</child>
      <pose>0.165 0 0.0875 0 0 0</pose>
      <axis>
        <xyz>0 0 1</xyz>
      </axis>
    </joint>

		<joint name="base_scan" type="fixed">
      <parent>base_link</parent>
      <child>lidar_link</child>
      <pose>0.1 0 0.14 0 0 0</pose>
      <axis>
        <xyz>0 0 1</xyz>
      </axis>
    </joint>

		<joint name="camera_optical_joint" type="fixed">
      <parent>camera_link</parent>
      <child>camera_color_link</child>
      <pose>0 0.015 0 0 1.57 0</pose>
      <axis>
        <xyz>0 0 1</xyz>
      </axis>
    </joint>

		<joint name="imu_joint" type="fixed">
      <parent>base_link</parent>
      <child>imu_link</child>
      <pose>0 0 0.0625 0 0 0</pose>
      <axis>
        <xyz>0 0 1</xyz>
      </axis>
    </joint>

		<!--PLUGINS-->

		<plugin name="wrv3_diff_drive" filename="libgazebo_ros_diff_drive.so">
      <ros>
        <!-- <namespace>/wrv3</namespace> -->
      </ros>

      <update_rate>30</update_rate>

      <!-- wheels -->
      <left_joint>wheell_joint</left_joint>
      <right_joint>wheelr_joint</right_joint>

      <!-- kinematics -->
      <wheel_separation>0.2</wheel_separation>
      <wheel_diameter>0.1</wheel_diameter>

      <!-- limits -->
      <max_wheel_torque>20</max_wheel_torque>
      <max_wheel_acceleration>1.0</max_wheel_acceleration>

      <command_topic>cmd_vel</command_topic>

      <!-- output -->
      <publish_odom>true</publish_odom>
      <publish_odom_tf>true</publish_odom_tf>
      <publish_wheel_tf>false</publish_wheel_tf>

      <odometry_topic>odom</odometry_topic>
      <odometry_frame>odom</odometry_frame>
      <robot_base_frame>base_footprint</robot_base_frame>
    </plugin>

    <plugin name="wrv3_joint_state" filename="libgazebo_ros_joint_state_publisher.so">
      <ros>
        <!-- <namespace>/wrv3</namespace> -->
        <remapping>~/out:=joint_states</remapping>
      </ros>
      <update_rate>30</update_rate>
      <joint_name>wheell_joint</joint_name>
      <joint_name>wheelr_joint</joint_name>
    </plugin>

	</model>
</sdf>